Workbook

Sheet intro_20260622
B3: Example
C4: A | D4: D | E4: G | G4: 1 | H4: 2 | I4: 3 | J4: 4 | K4: 5 | L4: 6 | M4: 7 | N4: 8
C6: B | D6: E | E6: H | G6: ð | H6: ï | I6: ñ | J6: ò | K6: ö | L6: ÷ | M6: õ | N6: ø
C8: C | D8: F | E8: I
B12: 22.06.2026 | C12: agv_table_center_link grasp_x_offset, _y_offset, _z_offset | D12: pcd_bound_x | E12: pcd_bound_y | F12: pcd_bound_z | G12: graspness_th | H12: grasp_height_th | I12: grasp_cog_max_dist_th | J12: grasp_cog_min_dist_th | K12: cog_axis_projection_th | L12: t0_to_tcp joint
B13: Baseline1 | C13: (-0.7, 0.0, 0.131) | D13: (-0.3,0.4) | E13: (-0.4,0.4) | F13: (-0.01,0.3) | G13: 0.2 | H13: 0.002 | I13: - | J13: - | K13: - | L13: xyz=(0,0,0.25)
C14: reset_pose.position.x | D14: reset_pose.position.y | E14: reset_pose.position.z | F14: reset_pose.orientation.x | G14: reset_pose.orientation.y | H14: reset_pose.orientation.z | I14: reset_pose.orientation.w
C15: 1.447416 | D15: 3.302368 | E15: 1.365898 | F15: -0.009596 | G15: 0.999594 | H15: 0.025939 | I15: -0.006796
D18: UR10e | G18: 1 | H18: 2 | I18: 3 | J18: 4 | K18: 5 | L18: 6 | M18: 7 | N18: 8
G19: =sum_orient_20260622!Q2 -> 0.38888889 | H19: =sum_orient_20260622!Q3 -> 0.16666667 | I19: =sum_orient_20260622!Q4 -> 0 | J19: =sum_orient_20260622!Q5 -> 0 | K19: =sum_orient_20260622!Q6 -> 0.11111111 | L19: =sum_orient_20260622!Q7 -> 0.22222222 | M19: =sum_orient_20260622!Q8 -> 0 | N19: =sum_orient_20260622!Q9 -> 0.22222222
C20: A | D20: D | E20: G | G20: ð | H20: ï | I20: ñ | J20: ò | K20: ö | L20: ÷ | M20: õ | N20: ø
C21: =sum_pos_20260622!Q2 -> 0.16666667 | D21: =sum_pos_20260622!Q5 -> 0.083333333 | E21: =sum_pos_20260611!Q8 -> 0
C22: B | D22: E | E22: H
C23: =sum_pos_20260622!Q3 -> #DIV/0! | D23: =sum_pos_20260622!Q6 -> #DIV/0! | E23: =sum_pos_20260611!Q9 -> 0
C24: C | D24: F | E24: I
C25: =sum_pos_20260622!Q4 -> 0.16666667 | D25: =sum_pos_20260611!Q7 -> 0 | E25: =sum_pos_20260611!Q10 -> 0

Sheet result_20260622
A1: Orientation | B1: Position | C1: Trial | D1: Name | E1: Success | F1: Success after intervention | G1: Success if further action were taken | H1: Failed | I1: Grasp too loose | J1: Fell during turning around | K1: No poses generated | L1: Possible collision between links | M1: Grasp aborted due to joint limits | N1: Grasp in opposite direction | O1: Grasp point not good, potential failure | P1: Grasp point too high, placement needs manual adjustment | Q1: Grasp point too low, placement distant from holder | R1: Object not face out after placement
A2: 1 | B2: A | C2: 1 | D2: =A2&"-"&B2&"-"&C2 -> 1-A-1 | H2: 1 | I2: 1
A3: 1 | B3: A | C3: 2 | D3: =A3&"-"&B3&"-"&C3 -> 1-A-2 | H3: 1 | I3: 1
A4: 1 | B4: A | C4: 3 | D4: =A4&"-"&B4&"-"&C4 -> 1-A-3 | H4: 1 | I4: 1
A5: 1 | B5: C | C5: 1 | D5: =A5&"-"&B5&"-"&C5 -> 1-C-1 | H5: 1 | I5: 1
A6: 1 | B6: C | C6: 2 | D6: =A6&"-"&B6&"-"&C6 -> 1-C-2 | H6: 1 | I6: 1
A7: 1 | B7: C | C7: 3 | D7: =A7&"-"&B7&"-"&C7 -> 1-C-3 | H7: 1 | I7: 1
A8: 1 | B8: D | C8: 1 | D8: =A8&"-"&B8&"-"&C8 -> 1-D-1 | H8: 1 | I8: 1
A9: 1 | B9: D | C9: 2 | D9: =A9&"-"&B9&"-"&C9 -> 1-D-2 | F9: 1 | N9: 1
A10: 1 | B10: D | C10: 3 | D10: =A10&"-"&B10&"-"&C10 -> 1-D-3 | H10: 1 | I10: 1
A11: 1 | B11: F | C11: 1 | D11: =A11&"-"&B11&"-"&C11 -> 1-F-1 | F11: 1 | Q11: 1
A12: 1 | B12: F | C12: 2 | D12: =A12&"-"&B12&"-"&C12 -> 1-F-2 | F12: 1 | Q12: 1
A13: 1 | B13: F | C13: 3 | D13: =A13&"-"&B13&"-"&C13 -> 1-F-3 | F13: 1 | Q13: 1
A14: 1 | B14: G | C14: 1 | D14: =A14&"-"&B14&"-"&C14 -> 1-G-1 | F14: 1 | N14: 1
A15: 1 | B15: G | C15: 2 | D15: =A15&"-"&B15&"-"&C15 -> 1-G-2 | G15: 1 | O15: 1
A16: 1 | B16: G | C16: 3 | D16: =A16&"-"&B16&"-"&C16 -> 1-G-3 | H16: 1 | I16: 1
A17: 1 | B17: I | C17: 1 | D17: =A17&"-"&B17&"-"&C17 -> 1-I-1 | H17: 1 | I17: 1
A18: 1 | B18: I | C18: 2 | D18: =A18&"-"&B18&"-"&C18 -> 1-I-2 | F18: 1 | R18: 1
A19: 1 | B19: I | C19: 3 | D19: =A19&"-"&B19&"-"&C19 -> 1-I-3 | F19: 1 | R19: 1
A20: 2 | B20: A | C20: 1 | D20: =A20&"-"&B20&"-"&C20 -> 2-A-1 | H20: 1 | I20: 1
A21: 2 | B21: A | C21: 2 | D21: =A21&"-"&B21&"-"&C21 -> 2-A-2 | F21: 1 | Q21: 1
A22: 2 | B22: A | C22: 3 | D22: =A22&"-"&B22&"-"&C22 -> 2-A-3 | H22: 1 | I22: 1
A23: 2 | B23: C | C23: 1 | D23: =A23&"-"&B23&"-"&C23 -> 2-C-1 | H23: 1 | I23: 1
A24: 2 | B24: C | C24: 2 | D24: =A24&"-"&B24&"-"&C24 -> 2-C-2 | H24: 1 | I24: 1
A25: 2 | B25: C | C25: 3 | D25: =A25&"-"&B25&"-"&C25 -> 2-C-3 | H25: 1 | I25: 1
A26: 2 | B26: D | C26: 1 | D26: =A26&"-"&B26&"-"&C26 -> 2-D-1 | G26: 1 | Q26: 1
A27: 2 | B27: D | C27: 2 | D27: =A27&"-"&B27&"-"&C27 -> 2-D-2 | H27: 1 | I27: 1
A28: 2 | B28: D | C28: 3 | D28: =A28&"-"&B28&"-"&C28 -> 2-D-3 | H28: 1 | J28: 1
A29: 2 | B29: F | C29: 1 | D29: =A29&"-"&B29&"-"&C29 -> 2-F-1 | H29: 1 | I29: 1
A30: 2 | B30: F | C30: 2 | D30: =A30&"-"&B30&"-"&C30 -> 2-F-2 | H30: 1 | I30: 1
A31: 2 | B31: F | C31: 3 | D31: =A31&"-"&B31&"-"&C31 -> 2-F-3 | H31: 1 | I31: 1
A32: 2 | B32: G | C32: 1 | D32: =A32&"-"&B32&"-"&C32 -> 2-G-1 | H32: 1 | I32: 1
A33: 2 | B33: G | C33: 2 | D33: =A33&"-"&B33&"-"&C33 -> 2-G-2 | F33: 1 | N33: 1
A34: 2 | B34: G | C34: 3 | D34: =A34&"-"&B34&"-"&C34 -> 2-G-3 | H34: 1 | I34: 1
A35: 2 | B35: I | C35: 1 | D35: =A35&"-"&B35&"-"&C35 -> 2-I-1 | H35: 1 | I35: 1
A36: 2 | B36: I | C36: 2 | D36: =A36&"-"&B36&"-"&C36 -> 2-I-2 | H36: 1 | I36: 1
A37: 2 | B37: I | C37: 3 | D37: =A37&"-"&B37&"-"&C37 -> 2-I-3 | F37: 1 | N37: 1
A38: 3 | B38: A | C38: 1 | D38: =A38&"-"&B38&"-"&C38 -> 3-A-1 | H38: 1 | I38: 1
A39: 3 | B39: A | C39: 2 | D39: =A39&"-"&B39&"-"&C39 -> 3-A-2 | H39: 1 | I39: 1
A40: 3 | B40: A | C40: 3 | D40: =A40&"-"&B40&"-"&C40 -> 3-A-3 | H40: 1 | I40: 1
...

Sheet sum_orient_20260622
A1: Orientation | B1: Success | C1: Success after intervention | D1: Success if further action were taken | E1: Failed | F1: Grasp point not good, potential failure | G1: No poses generated | H1: Grasp too loose | I1: Fell during turning around | J1: Grasp point too high, placement needs manual adjustment | K1: Grasp point too low, placement distant from holder | L1: Grasp in opposite direction | M1: Possible collision between links | N1: Grasp aborted due to joint limits | O1: Object not face out after placement | P1: Trials | Q1: Success rate(S+PS)
A2: 1 | B2: =SUMIF(result_20260622!$A:$A,sum_orient_20260622!$A2,INDEX(result_20260622!$A:$Z,0,MATCH(sum_orient_20260622!B$1,result_20260622!$1:$1,0))) -> 0 | C2: =SUMIF(result_20260622!$A:$A,sum_orient_20260622!$A2,INDEX(result_20260622!$A:$Z,0,MATCH(sum_orient_20260622!C$1,result_20260622!$1:$1,0))) -> 7 | D2: =SUMIF(result_20260622!$A:$A,sum_orient_20260622!$A2,INDEX(result_20260622!$A:$Z,0,MATCH(sum_orient_20260622!D$1,result_20260622!$1:$1,0))) -> 1 | E2: =SUMIF(result_20260622!$A:$A,sum_orient_20260622!$A2,INDEX(result_20260622!$A:$Z,0,MATCH(sum_orient_20260622!E$1,result_20260622!$1:$1,0))) -> 10 | F2: =SUMIF(result_20260622!$A:$A,sum_orient_20260622!$A2,INDEX(result_20260622!$A:$Z,0,MATCH(sum_orient_20260622!F$1,result_20260622!$1:$1,0))) -> 1 | G2: =SUMIF(result_20260622!$A:$A,sum_orient_20260622!$A2,INDEX(result_20260622!$A:$Z,0,MATCH(sum_orient_20260622!G$1,result_20260622!$1:$1,0))) -> 0 | H2: =SUMIF(result_20260622!$A:$A,sum_orient_20260622!$A2,INDEX(result_20260622!$A:$Z,0,MATCH(sum_orient_20260622!H$1,result_20260622!$1:$1,0))) -> 10 | I2: =SUMIF(result_20260622!$A:$A,sum_orient_20260622!$A2,INDEX(result_20260622!$A:$Z,0,MATCH(sum_orient_20260622!I$1,result_20260622!$1:$1,0))) -> 0 | ... O2: =SUMIF(result_20260622!$A:$A,sum_orient_20260622!$A2,INDEX(result_20260622!$A:$Z,0,MATCH(sum_orient_20260622!O$1,result_20260622!$1:$1,0))) -> 2 | P2: =SUM(B2:E2) -> 18 | Q2: =SUM(B2+C2)/P2 -> 0.38888889
A3: 2 | B3: =SUMIF(result_20260622!$A:$A,sum_orient_20260622!$A3,INDEX(result_20260622!$A:$Z,0,MATCH(sum_orient_20260622!B$1,result_20260622!$1:$1,0))) -> 0 | C3: =SUMIF(result_20260622!$A:$A,sum_orient_20260622!$A3,INDEX(result_20260622!$A:$Z,0,MATCH(sum_orient_20260622!C$1,result_20260622!$1:$1,0))) -> 3 | D3: =SUMIF(result_20260622!$A:$A,sum_orient_20260622!$A3,INDEX(result_20260622!$A:$Z,0,MATCH(sum_orient_20260622!D$1,result_20260622!$1:$1,0))) -> 1 | E3: =SUMIF(result_20260622!$A:$A,sum_orient_20260622!$A3,INDEX(result_20260622!$A:$Z,0,MATCH(sum_orient_20260622!E$1,result_20260622!$1:$1,0))) -> 14 | F3: =SUMIF(result_20260622!$A:$A,sum_orient_20260622!$A3,INDEX(result_20260622!$A:$Z,0,MATCH(sum_orient_20260622!F$1,result_20260622!$1:$1,0))) -> 0 | G3: =SUMIF(result_20260622!$A:$A,sum_orient_20260622!$A3,INDEX(result_20260622!$A:$Z,0,MATCH(sum_orient_20260622!G$1,result_20260622!$1:$1,0))) -> 0 | H3: =SUMIF(result_20260622!$A:$A,sum_orient_20260622!$A3,INDEX(result_20260622!$A:$Z,0,MATCH(sum_orient_20260622!H$1,result_20260622!$1:$1,0))) -> 13 | I3: =SUMIF(result_20260622!$A:$A,sum_orient_20260622!$A3,INDEX(result_20260622!$A:$Z,0,MATCH(sum_orient_20260622!I$1,result_20260622!$1:$1,0))) -> 1 | ... O3: =SUMIF(result_20260622!$A:$A,sum_orient_20260622!$A3,INDEX(result_20260622!$A:$Z,0,MATCH(sum_orient_20260622!O$1,result_20260622!$1:$1,0))) -> 0 | P3: =SUM(B3:E3) -> 18 | Q3: =SUM(B3+C3)/P3 -> 0.16666667
A4: 3 | B4: =SUMIF(result_20260622!$A:$A,sum_orient_20260622!$A4,INDEX(result_20260622!$A:$Z,0,MATCH(sum_orient_20260622!B$1,result_20260622!$1:$1,0))) -> 0 | C4: =SUMIF(result_20260622!$A:$A,sum_orient_20260622!$A4,INDEX(result_20260622!$A:$Z,0,MATCH(sum_orient_20260622!C$1,result_20260622!$1:$1,0))) -> 0 | D4: =SUMIF(result_20260622!$A:$A,sum_orient_20260622!$A4,INDEX(result_20260622!$A:$Z,0,MATCH(sum_orient_20260622!D$1,result_20260622!$1:$1,0))) -> 0 | E4: =SUMIF(result_20260622!$A:$A,sum_orient_20260622!$A4,INDEX(result_20260622!$A:$Z,0,MATCH(sum_orient_20260622!E$1,result_20260622!$1:$1,0))) -> 18 | F4: =SUMIF(result_20260622!$A:$A,sum_orient_20260622!$A4,INDEX(result_20260622!$A:$Z,0,MATCH(sum_orient_20260622!F$1,result_20260622!$1:$1,0))) -> 0 | G4: =SUMIF(result_20260622!$A:$A,sum_orient_20260622!$A4,INDEX(result_20260622!$A:$Z,0,MATCH(sum_orient_20260622!G$1,result_20260622!$1:$1,0))) -> 0 | H4: =SUMIF(result_20260622!$A:$A,sum_orient_20260622!$A4,INDEX(result_20260622!$A:$Z,0,MATCH(sum_orient_20260622!H$1,result_20260622!$1:$1,0))) -> 18 | I4: =SUMIF(result_20260622!$A:$A,sum_orient_20260622!$A4,INDEX(result_20260622!$A:$Z,0,MATCH(sum_orient_20260622!I$1,result_20260622!$1:$1,0))) -> 0 | ... O4: =SUMIF(result_20260622!$A:$A,sum_orient_20260622!$A4,INDEX(result_20260622!$A:$Z,0,MATCH(sum_orient_20260622!O$1,result_20260622!$1:$1,0))) -> 0 | P4: =SUM(B4:E4) -> 18 | Q4: =SUM(B4+C4)/P4 -> 0
A5: 4 | B5: =SUMIF(result_20260622!$A:$A,sum_orient_20260622!$A5,INDEX(result_20260622!$A:$Z,0,MATCH(sum_orient_20260622!B$1,result_20260622!$1:$1,0))) -> 0 | C5: =SUMIF(result_20260622!$A:$A,sum_orient_20260622!$A5,INDEX(result_20260622!$A:$Z,0,MATCH(sum_orient_20260622!C$1,result_20260622!$1:$1,0))) -> 0 | D5: =SUMIF(result_20260622!$A:$A,sum_orient_20260622!$A5,INDEX(result_20260622!$A:$Z,0,MATCH(sum_orient_20260622!D$1,result_20260622!$1:$1,0))) -> 4 | E5: =SUMIF(result_20260622!$A:$A,sum_orient_20260622!$A5,INDEX(result_20260622!$A:$Z,0,MATCH(sum_orient_20260622!E$1,result_20260622!$1:$1,0))) -> 14 | F5: =SUMIF(result_20260622!$A:$A,sum_orient_20260622!$A5,INDEX(result_20260622!$A:$Z,0,MATCH(sum_orient_20260622!F$1,result_20260622!$1:$1,0))) -> 0 | G5: =SUMIF(result_20260622!$A:$A,sum_orient_20260622!$A5,INDEX(result_20260622!$A:$Z,0,MATCH(sum_orient_20260622!G$1,result_20260622!$1:$1,0))) -> 0 | H5: =SUMIF(result_20260622!$A:$A,sum_orient_20260622!$A5,INDEX(result_20260622!$A:$Z,0,MATCH(sum_orient_20260622!H$1,result_20260622!$1:$1,0))) -> 14 | I5: =SUMIF(result_20260622!$A:$A,sum_orient_20260622!$A5,INDEX(result_20260622!$A:$Z,0,MATCH(sum_orient_20260622!I$1,result_20260622!$1:$1,0))) -> 0 | ... O5: =SUMIF(result_20260622!$A:$A,sum_orient_20260622!$A5,INDEX(result_20260622!$A:$Z,0,MATCH(sum_orient_20260622!O$1,result_20260622!$1:$1,0))) -> 0 | P5: =SUM(B5:E5) -> 18 | Q5: =SUM(B5+C5)/P5 -> 0
A6: 5 | B6: =SUMIF(result_20260622!$A:$A,sum_orient_20260622!$A6,INDEX(result_20260622!$A:$Z,0,MATCH(sum_orient_20260622!B$1,result_20260622!$1:$1,0))) -> 0 | C6: =SUMIF(result_20260622!$A:$A,sum_orient_20260622!$A6,INDEX(result_20260622!$A:$Z,0,MATCH(sum_orient_20260622!C$1,result_20260622!$1:$1,0))) -> 2 | D6: =SUMIF(result_20260622!$A:$A,sum_orient_20260622!$A6,INDEX(result_20260622!$A:$Z,0,MATCH(sum_orient_20260622!D$1,result_20260622!$1:$1,0))) -> 1 | E6: =SUMIF(result_20260622!$A:$A,sum_orient_20260622!$A6,INDEX(result_20260622!$A:$Z,0,MATCH(sum_orient_20260622!E$1,result_20260622!$1:$1,0))) -> 15 | F6: =SUMIF(result_20260622!$A:$A,sum_orient_20260622!$A6,INDEX(result_20260622!$A:$Z,0,MATCH(sum_orient_20260622!F$1,result_20260622!$1:$1,0))) -> 0 | G6: =SUMIF(result_20260622!$A:$A,sum_orient_20260622!$A6,INDEX(result_20260622!$A:$Z,0,MATCH(sum_orient_20260622!G$1,result_20260622!$1:$1,0))) -> 0 | H6: =SUMIF(result_20260622!$A:$A,sum_orient_20260622!$A6,INDEX(result_20260622!$A:$Z,0,MATCH(sum_orient_20260622!H$1,result_20260622!$1:$1,0))) -> 15 | I6: =SUMIF(result_20260622!$A:$A,sum_orient_20260622!$A6,INDEX(result_20260622!$A:$Z,0,MATCH(sum_orient_20260622!I$1,result_20260622!$1:$1,0))) -> 0 | ... O6: =SUMIF(result_20260622!$A:$A,sum_orient_20260622!$A6,INDEX(result_20260622!$A:$Z,0,MATCH(sum_orient_20260622!O$1,result_20260622!$1:$1,0))) -> 0 | P6: =SUM(B6:E6) -> 18 | Q6: =SUM(B6+C6)/P6 -> 0.11111111
A7: 6 | B7: =SUMIF(result_20260622!$A:$A,sum_orient_20260622!$A7,INDEX(result_20260622!$A:$Z,0,MATCH(sum_orient_20260622!B$1,result_20260622!$1:$1,0))) -> 0 | C7: =SUMIF(result_20260622!$A:$A,sum_orient_20260622!$A7,INDEX(result_20260622!$A:$Z,0,MATCH(sum_orient_20260622!C$1,result_20260622!$1:$1,0))) -> 4 | D7: =SUMIF(result_20260622!$A:$A,sum_orient_20260622!$A7,INDEX(result_20260622!$A:$Z,0,MATCH(sum_orient_20260622!D$1,result_20260622!$1:$1,0))) -> 1 | E7: =SUMIF(result_20260622!$A:$A,sum_orient_20260622!$A7,INDEX(result_20260622!$A:$Z,0,MATCH(sum_orient_20260622!E$1,result_20260622!$1:$1,0))) -> 13 | F7: =SUMIF(result_20260622!$A:$A,sum_orient_20260622!$A7,INDEX(result_20260622!$A:$Z,0,MATCH(sum_orient_20260622!F$1,result_20260622!$1:$1,0))) -> 0 | G7: =SUMIF(result_20260622!$A:$A,sum_orient_20260622!$A7,INDEX(result_20260622!$A:$Z,0,MATCH(sum_orient_20260622!G$1,result_20260622!$1:$1,0))) -> 0 | H7: =SUMIF(result_20260622!$A:$A,sum_orient_20260622!$A7,INDEX(result_20260622!$A:$Z,0,MATCH(sum_orient_20260622!H$1,result_20260622!$1:$1,0))) -> 12 | I7: =SUMIF(result_20260622!$A:$A,sum_orient_20260622!$A7,INDEX(result_20260622!$A:$Z,0,MATCH(sum_orient_20260622!I$1,result_20260622!$1:$1,0))) -> 1 | ... O7: =SUMIF(result_20260622!$A:$A,sum_orient_20260622!$A7,INDEX(result_20260622!$A:$Z,0,MATCH(sum_orient_20260622!O$1,result_20260622!$1:$1,0))) -> 0 | P7: =SUM(B7:E7) -> 18 | Q7: =SUM(B7+C7)/P7 -> 0.22222222
A8: 7 | B8: =SUMIF(result_20260622!$A:$A,sum_orient_20260622!$A8,INDEX(result_20260622!$A:$Z,0,MATCH(sum_orient_20260622!B$1,result_20260622!$1:$1,0))) -> 0 | C8: =SUMIF(result_20260622!$A:$A,sum_orient_20260622!$A8,INDEX(result_20260622!$A:$Z,0,MATCH(sum_orient_20260622!C$1,result_20260622!$1:$1,0))) -> 0 | D8: =SUMIF(result_20260622!$A:$A,sum_orient_20260622!$A8,INDEX(result_20260622!$A:$Z,0,MATCH(sum_orient_20260622!D$1,result_20260622!$1:$1,0))) -> 2 | E8: =SUMIF(result_20260622!$A:$A,sum_orient_20260622!$A8,INDEX(result_20260622!$A:$Z,0,MATCH(sum_orient_20260622!E$1,result_20260622!$1:$1,0))) -> 16 | F8: =SUMIF(result_20260622!$A:$A,sum_orient_20260622!$A8,INDEX(result_20260622!$A:$Z,0,MATCH(sum_orient_20260622!F$1,result_20260622!$1:$1,0))) -> 2 | G8: =SUMIF(result_20260622!$A:$A,sum_orient_20260622!$A8,INDEX(result_20260622!$A:$Z,0,MATCH(sum_orient_20260622!G$1,result_20260622!$1:$1,0))) -> 0 | H8: =SUMIF(result_20260622!$A:$A,sum_orient_20260622!$A8,INDEX(result_20260622!$A:$Z,0,MATCH(sum_orient_20260622!H$1,result_20260622!$1:$1,0))) -> 5 | I8: =SUMIF(result_20260622!$A:$A,sum_orient_20260622!$A8,INDEX(result_20260622!$A:$Z,0,MATCH(sum_orient_20260622!I$1,result_20260622!$1:$1,0))) -> 0 | ... O8: =SUMIF(result_20260622!$A:$A,sum_orient_20260622!$A8,INDEX(result_20260622!$A:$Z,0,MATCH(sum_orient_20260622!O$1,result_20260622!$1:$1,0))) -> 0 | P8: =SUM(B8:E8) -> 18 | Q8: =SUM(B8+C8)/P8 -> 0
A9: 8 | B9: =SUMIF(result_20260622!$A:$A,sum_orient_20260622!$A9,INDEX(result_20260622!$A:$Z,0,MATCH(sum_orient_20260622!B$1,result_20260622!$1:$1,0))) -> 0 | C9: =SUMIF(result_20260622!$A:$A,sum_orient_20260622!$A9,INDEX(result_20260622!$A:$Z,0,MATCH(sum_orient_20260622!C$1,result_20260622!$1:$1,0))) -> 4 | D9: =SUMIF(result_20260622!$A:$A,sum_orient_20260622!$A9,INDEX(result_20260622!$A:$Z,0,MATCH(sum_orient_20260622!D$1,result_20260622!$1:$1,0))) -> 0 | E9: =SUMIF(result_20260622!$A:$A,sum_orient_20260622!$A9,INDEX(result_20260622!$A:$Z,0,MATCH(sum_orient_20260622!E$1,result_20260622!$1:$1,0))) -> 14 | F9: =SUMIF(result_20260622!$A:$A,sum_orient_20260622!$A9,INDEX(result_20260622!$A:$Z,0,MATCH(sum_orient_20260622!F$1,result_20260622!$1:$1,0))) -> 1 | G9: =SUMIF(result_20260622!$A:$A,sum_orient_20260622!$A9,INDEX(result_20260622!$A:$Z,0,MATCH(sum_orient_20260622!G$1,result_20260622!$1:$1,0))) -> 0 | H9: =SUMIF(result_20260622!$A:$A,sum_orient_20260622!$A9,INDEX(result_20260622!$A:$Z,0,MATCH(sum_orient_20260622!H$1,result_20260622!$1:$1,0))) -> 14 | I9: =SUMIF(result_20260622!$A:$A,sum_orient_20260622!$A9,INDEX(result_20260622!$A:$Z,0,MATCH(sum_orient_20260622!I$1,result_20260622!$1:$1,0))) -> 0 | ... O9: =SUMIF(result_20260622!$A:$A,sum_orient_20260622!$A9,INDEX(result_20260622!$A:$Z,0,MATCH(sum_orient_20260622!O$1,result_20260622!$1:$1,0))) -> 0 | P9: =SUM(B9:E9) -> 18 | Q9: =SUM(B9+C9)/P9 -> 0.22222222
A10: SUM | B10: =SUM(B2:B9) -> 0 | C10: =SUM(C2:C9) -> 20 | D10: =SUM(D2:D9) -> 10 | E10: =SUM(E2:E9) -> 114 | F10: =SUM(F2:F9) -> 4 | G10: =SUM(G2:G9) -> 0 | H10: =SUM(H2:H9) -> 101 | I10: =SUM(I2:I9) -> 2 | ... P10: =SUM(P2:P9) -> 144 | Q10: =SUM(B10+C10)/P10 -> 0.13888889
A12: Excluding Orient. 3,5,7
A13: Orientation | B13: Success | C13: Success after intervention | D13: Success if further action were taken | E13: Failed | F13: Grasp point not good, potential failure | G13: No poses generated | H13: Grasp too loose | I13: Fell during turning around | J13: Grasp point too high, placement needs manual adjustment | K13: Grasp point too low, placement distant from holder | L13: Grasp in opposite direction | M13: Possible collision between links | N13: Grasp aborted due to joint limits | O13: Object not face out after placement | P13: Trials | Q13: Success rate(S+PS)
A14: 1 | B14: =SUMIF(result_20260622!$A:$A,sum_orient_20260622!$A14,INDEX(result_20260622!$A:$Z,0,MATCH(sum_orient_20260622!B$1,result_20260622!$1:$1,0))) -> 0 | C14: =SUMIF(result_20260622!$A:$A,sum_orient_20260622!$A14,INDEX(result_20260622!$A:$Z,0,MATCH(sum_orient_20260622!C$1,result_20260622!$1:$1,0))) -> 7 | D14: =SUMIF(result_20260622!$A:$A,sum_orient_20260622!$A14,INDEX(result_20260622!$A:$Z,0,MATCH(sum_orient_20260622!D$1,result_20260622!$1:$1,0))) -> 1 | E14: =SUMIF(result_20260622!$A:$A,sum_orient_20260622!$A14,INDEX(result_20260622!$A:$Z,0,MATCH(sum_orient_20260622!E$1,result_20260622!$1:$1,0))) -> 10 | F14: =SUMIF(result_20260622!$A:$A,sum_orient_20260622!$A14,INDEX(result_20260622!$A:$Z,0,MATCH(sum_orient_20260622!F$1,result_20260622!$1:$1,0))) -> 1 | G14: =SUMIF(result_20260622!$A:$A,sum_orient_20260622!$A14,INDEX(result_20260622!$A:$Z,0,MATCH(sum_orient_20260622!G$1,result_20260622!$1:$1,0))) -> 0 | H14: =SUMIF(result_20260622!$A:$A,sum_orient_20260622!$A14,INDEX(result_20260622!$A:$Z,0,MATCH(sum_orient_20260622!H$1,result_20260622!$1:$1,0))) -> 10 | I14: =SUMIF(result_20260622!$A:$A,sum_orient_20260622!$A14,INDEX(result_20260622!$A:$Z,0,MATCH(sum_orient_20260622!I$1,result_20260622!$1:$1,0))) -> 0 | ... O14: =SUMIF(result_20260622!$A:$A,sum_orient_20260622!$A14,INDEX(result_20260622!$A:$Z,0,MATCH(sum_orient_20260622!O$1,result_20260622!$1:$1,0))) -> 2 | P14: =SUM(B14:E14) -> 18 | Q14: =SUM(B14+C14)/P14 -> 0.38888889
A15: 2 | B15: =SUMIF(result_20260622!$A:$A,sum_orient_20260622!$A15,INDEX(result_20260622!$A:$Z,0,MATCH(sum_orient_20260622!B$1,result_20260622!$1:$1,0))) -> 0 | C15: =SUMIF(result_20260622!$A:$A,sum_orient_20260622!$A15,INDEX(result_20260622!$A:$Z,0,MATCH(sum_orient_20260622!C$1,result_20260622!$1:$1,0))) -> 3 | D15: =SUMIF(result_20260622!$A:$A,sum_orient_20260622!$A15,INDEX(result_20260622!$A:$Z,0,MATCH(sum_orient_20260622!D$1,result_20260622!$1:$1,0))) -> 1 | E15: =SUMIF(result_20260622!$A:$A,sum_orient_20260622!$A15,INDEX(result_20260622!$A:$Z,0,MATCH(sum_orient_20260622!E$1,result_20260622!$1:$1,0))) -> 14 | F15: =SUMIF(result_20260622!$A:$A,sum_orient_20260622!$A15,INDEX(result_20260622!$A:$Z,0,MATCH(sum_orient_20260622!F$1,result_20260622!$1:$1,0))) -> 0 | G15: =SUMIF(result_20260622!$A:$A,sum_orient_20260622!$A15,INDEX(result_20260622!$A:$Z,0,MATCH(sum_orient_20260622!G$1,result_20260622!$1:$1,0))) -> 0 | H15: =SUMIF(result_20260622!$A:$A,sum_orient_20260622!$A15,INDEX(result_20260622!$A:$Z,0,MATCH(sum_orient_20260622!H$1,result_20260622!$1:$1,0))) -> 13 | I15: =SUMIF(result_20260622!$A:$A,sum_orient_20260622!$A15,INDEX(result_20260622!$A:$Z,0,MATCH(sum_orient_20260622!I$1,result_20260622!$1:$1,0))) -> 1 | ... O15: =SUMIF(result_20260622!$A:$A,sum_orient_20260622!$A15,INDEX(result_20260622!$A:$Z,0,MATCH(sum_orient_20260622!O$1,result_20260622!$1:$1,0))) -> 0 | P15: =SUM(B15:E15) -> 18 | Q15: =SUM(B15+C15)/P15 -> 0.16666667
A16: 4 | B16: =SUMIF(result_20260622!$A:$A,sum_orient_20260622!$A16,INDEX(result_20260622!$A:$Z,0,MATCH(sum_orient_20260622!B$1,result_20260622!$1:$1,0))) -> 0 | C16: =SUMIF(result_20260622!$A:$A,sum_orient_20260622!$A16,INDEX(result_20260622!$A:$Z,0,MATCH(sum_orient_20260622!C$1,result_20260622!$1:$1,0))) -> 0 | D16: =SUMIF(result_20260622!$A:$A,sum_orient_20260622!$A16,INDEX(result_20260622!$A:$Z,0,MATCH(sum_orient_20260622!D$1,result_20260622!$1:$1,0))) -> 4 | E16: =SUMIF(result_20260622!$A:$A,sum_orient_20260622!$A16,INDEX(result_20260622!$A:$Z,0,MATCH(sum_orient_20260622!E$1,result_20260622!$1:$1,0))) -> 14 | F16: =SUMIF(result_20260622!$A:$A,sum_orient_20260622!$A16,INDEX(result_20260622!$A:$Z,0,MATCH(sum_orient_20260622!F$1,result_20260622!$1:$1,0))) -> 0 | G16: =SUMIF(result_20260622!$A:$A,sum_orient_20260622!$A16,INDEX(result_20260622!$A:$Z,0,MATCH(sum_orient_20260622!G$1,result_20260622!$1:$1,0))) -> 0 | H16: =SUMIF(result_20260622!$A:$A,sum_orient_20260622!$A16,INDEX(result_20260622!$A:$Z,0,MATCH(sum_orient_20260622!H$1,result_20260622!$1:$1,0))) -> 14 | I16: =SUMIF(result_20260622!$A:$A,sum_orient_20260622!$A16,INDEX(result_20260622!$A:$Z,0,MATCH(sum_orient_20260622!I$1,result_20260622!$1:$1,0))) -> 0 | ... O16: =SUMIF(result_20260622!$A:$A,sum_orient_20260622!$A16,INDEX(result_20260622!$A:$Z,0,MATCH(sum_orient_20260622!O$1,result_20260622!$1:$1,0))) -> 0 | P16: =SUM(B16:E16) -> 18 | Q16: =SUM(B16+C16)/P16 -> 0
A17: 6 | B17: =SUMIF(result_20260622!$A:$A,sum_orient_20260622!$A17,INDEX(result_20260622!$A:$Z,0,MATCH(sum_orient_20260622!B$1,result_20260622!$1:$1,0))) -> 0 | C17: =SUMIF(result_20260622!$A:$A,sum_orient_20260622!$A17,INDEX(result_20260622!$A:$Z,0,MATCH(sum_orient_20260622!C$1,result_20260622!$1:$1,0))) -> 4 | D17: =SUMIF(result_20260622!$A:$A,sum_orient_20260622!$A17,INDEX(result_20260622!$A:$Z,0,MATCH(sum_orient_20260622!D$1,result_20260622!$1:$1,0))) -> 1 | E17: =SUMIF(result_20260622!$A:$A,sum_orient_20260622!$A17,INDEX(result_20260622!$A:$Z,0,MATCH(sum_orient_20260622!E$1,result_20260622!$1:$1,0))) -> 13 | F17: =SUMIF(result_20260622!$A:$A,sum_orient_20260622!$A17,INDEX(result_20260622!$A:$Z,0,MATCH(sum_orient_20260622!F$1,result_20260622!$1:$1,0))) -> 0 | G17: =SUMIF(result_20260622!$A:$A,sum_orient_20260622!$A17,INDEX(result_20260622!$A:$Z,0,MATCH(sum_orient_20260622!G$1,result_20260622!$1:$1,0))) -> 0 | H17: =SUMIF(result_20260622!$A:$A,sum_orient_20260622!$A17,INDEX(result_20260622!$A:$Z,0,MATCH(sum_orient_20260622!H$1,result_20260622!$1:$1,0))) -> 12 | I17: =SUMIF(result_20260622!$A:$A,sum_orient_20260622!$A17,INDEX(result_20260622!$A:$Z,0,MATCH(sum_orient_20260622!I$1,result_20260622!$1:$1,0))) -> 1 | ... O17: =SUMIF(result_20260622!$A:$A,sum_orient_20260622!$A17,INDEX(result_20260622!$A:$Z,0,MATCH(sum_orient_20260622!O$1,result_20260622!$1:$1,0))) -> 0 | P17: =SUM(B17:E17) -> 18 | Q17: =SUM(B17+C17)/P17 -> 0.22222222
A18: 8 | B18: =SUMIF(result_20260622!$A:$A,sum_orient_20260622!$A18,INDEX(result_20260622!$A:$Z,0,MATCH(sum_orient_20260622!B$1,result_20260622!$1:$1,0))) -> 0 | C18: =SUMIF(result_20260622!$A:$A,sum_orient_20260622!$A18,INDEX(result_20260622!$A:$Z,0,MATCH(sum_orient_20260622!C$1,result_20260622!$1:$1,0))) -> 4 | D18: =SUMIF(result_20260622!$A:$A,sum_orient_20260622!$A18,INDEX(result_20260622!$A:$Z,0,MATCH(sum_orient_20260622!D$1,result_20260622!$1:$1,0))) -> 0 | E18: =SUMIF(result_20260622!$A:$A,sum_orient_20260622!$A18,INDEX(result_20260622!$A:$Z,0,MATCH(sum_orient_20260622!E$1,result_20260622!$1:$1,0))) -> 14 | F18: =SUMIF(result_20260622!$A:$A,sum_orient_20260622!$A18,INDEX(result_20260622!$A:$Z,0,MATCH(sum_orient_20260622!F$1,result_20260622!$1:$1,0))) -> 1 | G18: =SUMIF(result_20260622!$A:$A,sum_orient_20260622!$A18,INDEX(result_20260622!$A:$Z,0,MATCH(sum_orient_20260622!G$1,result_20260622!$1:$1,0))) -> 0 | H18: =SUMIF(result_20260622!$A:$A,sum_orient_20260622!$A18,INDEX(result_20260622!$A:$Z,0,MATCH(sum_orient_20260622!H$1,result_20260622!$1:$1,0))) -> 14 | I18: =SUMIF(result_20260622!$A:$A,sum_orient_20260622!$A18,INDEX(result_20260622!$A:$Z,0,MATCH(sum_orient_20260622!I$1,result_20260622!$1:$1,0))) -> 0 | ... O18: =SUMIF(result_20260622!$A:$A,sum_orient_20260622!$A18,INDEX(result_20260622!$A:$Z,0,MATCH(sum_orient_20260622!O$1,result_20260622!$1:$1,0))) -> 0 | P18: =SUM(B18:E18) -> 18 | Q18: =SUM(B18+C18)/P18 -> 0.22222222
A19: SUM | B19: =SUM(B14:B18) -> 0 | C19: =SUM(C14:C18) -> 18 | D19: =SUM(D14:D18) -> 7 | E19: =SUM(E14:E18) -> 65 | F19: =SUM(F14:F18) -> 2 | G19: =SUM(G14:G18) -> 0 | H19: =SUM(H14:H18) -> 63 | I19: =SUM(I14:I18) -> 2 | ... P19: =SUM(P14:P18) -> 90 | Q19: =SUM(B19+C19)/P19 -> 0.2

Sheet sum_pos_20260622
A1: Position | B1: Success | C1: Success after intervention | D1: Success if further action were taken | E1: Failed | F1: Grasp point not good, potential failure | G1: No poses generated | H1: Fell during turning around | I1: Grasp too loose | J1: Grasp point too high, placement needs manual adjustment | K1: Grasp point too low, placement distant from holder | L1: Grasp in opposite direction | M1: Possible collision between links | N1: Grasp aborted due to joint limits | O1: Object not face out after placement | P1: Trials | Q1: Success rate(S+PS)
A2: A | B2: =SUMIF(result_20260622!$B:$B,sum_pos_20260622!$A2,INDEX(result_20260622!$A:$Z,0,MATCH(sum_pos_20260622!B$1,result_20260622!$1:$1,0))) -> 0 | C2: =SUMIF(result_20260622!$B:$B,sum_pos_20260622!$A2,INDEX(result_20260622!$A:$Z,0,MATCH(sum_pos_20260622!C$1,result_20260622!$1:$1,0))) -> 4 | D2: =SUMIF(result_20260622!$B:$B,sum_pos_20260622!$A2,INDEX(result_20260622!$A:$Z,0,MATCH(sum_pos_20260622!D$1,result_20260622!$1:$1,0))) -> 2 | E2: =SUMIF(result_20260622!$B:$B,sum_pos_20260622!$A2,INDEX(result_20260622!$A:$Z,0,MATCH(sum_pos_20260622!E$1,result_20260622!$1:$1,0))) -> 18 | F2: =SUMIF(result_20260622!$B:$B,sum_pos_20260622!$A2,INDEX(result_20260622!$A:$Z,0,MATCH(sum_pos_20260622!F$1,result_20260622!$1:$1,0))) -> 0 | G2: =SUMIF(result_20260622!$B:$B,sum_pos_20260622!$A2,INDEX(result_20260622!$A:$Z,0,MATCH(sum_pos_20260622!G$1,result_20260622!$1:$1,0))) -> 0 | H2: =SUMIF(result_20260622!$B:$B,sum_pos_20260622!$A2,INDEX(result_20260622!$A:$Z,0,MATCH(sum_pos_20260622!H$1,result_20260622!$1:$1,0))) -> 0 | I2: =SUMIF(result_20260622!$B:$B,sum_pos_20260622!$A2,INDEX(result_20260622!$A:$Z,0,MATCH(sum_pos_20260622!I$1,result_20260622!$1:$1,0))) -> 16 | ... O2: =SUMIF(result_20260622!$B:$B,sum_pos_20260622!$A2,INDEX(result_20260622!$A:$Z,0,MATCH(sum_pos_20260622!O$1,result_20260622!$1:$1,0))) -> 0 | P2: =SUM(B2:E2) -> 24 | Q2: =SUM(B2:C2)/P2 -> 0.16666667
A3: B | B3: =SUMIF(result_20260622!$B:$B,sum_pos_20260622!$A3,INDEX(result_20260622!$A:$Z,0,MATCH(sum_pos_20260622!B$1,result_20260622!$1:$1,0))) -> 0 | C3: =SUMIF(result_20260622!$B:$B,sum_pos_20260622!$A3,INDEX(result_20260622!$A:$Z,0,MATCH(sum_pos_20260622!C$1,result_20260622!$1:$1,0))) -> 0 | D3: =SUMIF(result_20260622!$B:$B,sum_pos_20260622!$A3,INDEX(result_20260622!$A:$Z,0,MATCH(sum_pos_20260622!D$1,result_20260622!$1:$1,0))) -> 0 | E3: =SUMIF(result_20260622!$B:$B,sum_pos_20260622!$A3,INDEX(result_20260622!$A:$Z,0,MATCH(sum_pos_20260622!E$1,result_20260622!$1:$1,0))) -> 0 | F3: =SUMIF(result_20260622!$B:$B,sum_pos_20260622!$A3,INDEX(result_20260622!$A:$Z,0,MATCH(sum_pos_20260622!F$1,result_20260622!$1:$1,0))) -> 0 | G3: =SUMIF(result_20260622!$B:$B,sum_pos_20260622!$A3,INDEX(result_20260622!$A:$Z,0,MATCH(sum_pos_20260622!G$1,result_20260622!$1:$1,0))) -> 0 | H3: =SUMIF(result_20260622!$B:$B,sum_pos_20260622!$A3,INDEX(result_20260622!$A:$Z,0,MATCH(sum_pos_20260622!H$1,result_20260622!$1:$1,0))) -> 0 | I3: =SUMIF(result_20260622!$B:$B,sum_pos_20260622!$A3,INDEX(result_20260622!$A:$Z,0,MATCH(sum_pos_20260622!I$1,result_20260622!$1:$1,0))) -> 0 | ... O3: =SUMIF(result_20260622!$B:$B,sum_pos_20260622!$A3,INDEX(result_20260622!$A:$Z,0,MATCH(sum_pos_20260622!O$1,result_20260622!$1:$1,0))) -> 0 | P3: =SUM(B3:E3) -> 0 | Q3: =SUM(B3:C3)/P3 -> #DIV/0!
A4: C | B4: =SUMIF(result_20260622!$B:$B,sum_pos_20260622!$A4,INDEX(result_20260622!$A:$Z,0,MATCH(sum_pos_20260622!B$1,result_20260622!$1:$1,0))) -> 0 | C4: =SUMIF(result_20260622!$B:$B,sum_pos_20260622!$A4,INDEX(result_20260622!$A:$Z,0,MATCH(sum_pos_20260622!C$1,result_20260622!$1:$1,0))) -> 4 | D4: =SUMIF(result_20260622!$B:$B,sum_pos_20260622!$A4,INDEX(result_20260622!$A:$Z,0,MATCH(sum_pos_20260622!D$1,result_20260622!$1:$1,0))) -> 0 | E4: =SUMIF(result_20260622!$B:$B,sum_pos_20260622!$A4,INDEX(result_20260622!$A:$Z,0,MATCH(sum_pos_20260622!E$1,result_20260622!$1:$1,0))) -> 20 | F4: =SUMIF(result_20260622!$B:$B,sum_pos_20260622!$A4,INDEX(result_20260622!$A:$Z,0,MATCH(sum_pos_20260622!F$1,result_20260622!$1:$1,0))) -> 0 | G4: =SUMIF(result_20260622!$B:$B,sum_pos_20260622!$A4,INDEX(result_20260622!$A:$Z,0,MATCH(sum_pos_20260622!G$1,result_20260622!$1:$1,0))) -> 0 | H4: =SUMIF(result_20260622!$B:$B,sum_pos_20260622!$A4,INDEX(result_20260622!$A:$Z,0,MATCH(sum_pos_20260622!H$1,result_20260622!$1:$1,0))) -> 0 | I4: =SUMIF(result_20260622!$B:$B,sum_pos_20260622!$A4,INDEX(result_20260622!$A:$Z,0,MATCH(sum_pos_20260622!I$1,result_20260622!$1:$1,0))) -> 17 | ... O4: =SUMIF(result_20260622!$B:$B,sum_pos_20260622!$A4,INDEX(result_20260622!$A:$Z,0,MATCH(sum_pos_20260622!O$1,result_20260622!$1:$1,0))) -> 0 | P4: =SUM(B4:E4) -> 24 | Q4: =SUM(B4:C4)/P4 -> 0.16666667
A5: D | B5: =SUMIF(result_20260622!$B:$B,sum_pos_20260622!$A5,INDEX(result_20260622!$A:$Z,0,MATCH(sum_pos_20260622!B$1,result_20260622!$1:$1,0))) -> 0 | C5: =SUMIF(result_20260622!$B:$B,sum_pos_20260622!$A5,INDEX(result_20260622!$A:$Z,0,MATCH(sum_pos_20260622!C$1,result_20260622!$1:$1,0))) -> 2 | D5: =SUMIF(result_20260622!$B:$B,sum_pos_20260622!$A5,INDEX(result_20260622!$A:$Z,0,MATCH(sum_pos_20260622!D$1,result_20260622!$1:$1,0))) -> 3 | E5: =SUMIF(result_20260622!$B:$B,sum_pos_20260622!$A5,INDEX(result_20260622!$A:$Z,0,MATCH(sum_pos_20260622!E$1,result_20260622!$1:$1,0))) -> 19 | F5: =SUMIF(result_20260622!$B:$B,sum_pos_20260622!$A5,INDEX(result_20260622!$A:$Z,0,MATCH(sum_pos_20260622!F$1,result_20260622!$1:$1,0))) -> 1 | G5: =SUMIF(result_20260622!$B:$B,sum_pos_20260622!$A5,INDEX(result_20260622!$A:$Z,0,MATCH(sum_pos_20260622!G$1,result_20260622!$1:$1,0))) -> 0 | H5: =SUMIF(result_20260622!$B:$B,sum_pos_20260622!$A5,INDEX(result_20260622!$A:$Z,0,MATCH(sum_pos_20260622!H$1,result_20260622!$1:$1,0))) -> 1 | I5: =SUMIF(result_20260622!$B:$B,sum_pos_20260622!$A5,INDEX(result_20260622!$A:$Z,0,MATCH(sum_pos_20260622!I$1,result_20260622!$1:$1,0))) -> 15 | ... O5: =SUMIF(result_20260622!$B:$B,sum_pos_20260622!$A5,INDEX(result_20260622!$A:$Z,0,MATCH(sum_pos_20260622!O$1,result_20260622!$1:$1,0))) -> 0 | P5: =SUM(B5:E5) -> 24 | Q5: =SUM(B5:C5)/P5 -> 0.083333333
A6: E | B6: =SUMIF(result_20260622!$B:$B,sum_pos_20260622!$A6,INDEX(result_20260622!$A:$Z,0,MATCH(sum_pos_20260622!B$1,result_20260622!$1:$1,0))) -> 0 | C6: =SUMIF(result_20260622!$B:$B,sum_pos_20260622!$A6,INDEX(result_20260622!$A:$Z,0,MATCH(sum_pos_20260622!C$1,result_20260622!$1:$1,0))) -> 0 | D6: =SUMIF(result_20260622!$B:$B,sum_pos_20260622!$A6,INDEX(result_20260622!$A:$Z,0,MATCH(sum_pos_20260622!D$1,result_20260622!$1:$1,0))) -> 0 | E6: =SUMIF(result_20260622!$B:$B,sum_pos_20260622!$A6,INDEX(result_20260622!$A:$Z,0,MATCH(sum_pos_20260622!E$1,result_20260622!$1:$1,0))) -> 0 | F6: =SUMIF(result_20260622!$B:$B,sum_pos_20260622!$A6,INDEX(result_20260622!$A:$Z,0,MATCH(sum_pos_20260622!F$1,result_20260622!$1:$1,0))) -> 0 | G6: =SUMIF(result_20260622!$B:$B,sum_pos_20260622!$A6,INDEX(result_20260622!$A:$Z,0,MATCH(sum_pos_20260622!G$1,result_20260622!$1:$1,0))) -> 0 | H6: =SUMIF(result_20260622!$B:$B,sum_pos_20260622!$A6,INDEX(result_20260622!$A:$Z,0,MATCH(sum_pos_20260622!H$1,result_20260622!$1:$1,0))) -> 0 | I6: =SUMIF(result_20260622!$B:$B,sum_pos_20260622!$A6,INDEX(result_20260622!$A:$Z,0,MATCH(sum_pos_20260622!I$1,result_20260622!$1:$1,0))) -> 0 | ... O6: =SUMIF(result_20260622!$B:$B,sum_pos_20260622!$A6,INDEX(result_20260622!$A:$Z,0,MATCH(sum_pos_20260622!O$1,result_20260622!$1:$1,0))) -> 0 | P6: =SUM(B6:E6) -> 0 | Q6: =SUM(B6:C6)/P6 -> #DIV/0!
A7: F | B7: =SUMIF(result_20260622!$B:$B,sum_pos_20260622!$A7,INDEX(result_20260622!$A:$Z,0,MATCH(sum_pos_20260622!B$1,result_20260622!$1:$1,0))) -> 0 | C7: =SUMIF(result_20260622!$B:$B,sum_pos_20260622!$A7,INDEX(result_20260622!$A:$Z,0,MATCH(sum_pos_20260622!C$1,result_20260622!$1:$1,0))) -> 4 | D7: =SUMIF(result_20260622!$B:$B,sum_pos_20260622!$A7,INDEX(result_20260622!$A:$Z,0,MATCH(sum_pos_20260622!D$1,result_20260622!$1:$1,0))) -> 2 | E7: =SUMIF(result_20260622!$B:$B,sum_pos_20260622!$A7,INDEX(result_20260622!$A:$Z,0,MATCH(sum_pos_20260622!E$1,result_20260622!$1:$1,0))) -> 18 | F7: =SUMIF(result_20260622!$B:$B,sum_pos_20260622!$A7,INDEX(result_20260622!$A:$Z,0,MATCH(sum_pos_20260622!F$1,result_20260622!$1:$1,0))) -> 0 | G7: =SUMIF(result_20260622!$B:$B,sum_pos_20260622!$A7,INDEX(result_20260622!$A:$Z,0,MATCH(sum_pos_20260622!G$1,result_20260622!$1:$1,0))) -> 0 | H7: =SUMIF(result_20260622!$B:$B,sum_pos_20260622!$A7,INDEX(result_20260622!$A:$Z,0,MATCH(sum_pos_20260622!H$1,result_20260622!$1:$1,0))) -> 0 | I7: =SUMIF(result_20260622!$B:$B,sum_pos_20260622!$A7,INDEX(result_20260622!$A:$Z,0,MATCH(sum_pos_20260622!I$1,result_20260622!$1:$1,0))) -> 15 | ... O7: =SUMIF(result_20260622!$B:$B,sum_pos_20260622!$A7,INDEX(result_20260622!$A:$Z,0,MATCH(sum_pos_20260622!O$1,result_20260622!$1:$1,0))) -> 0 | P7: =SUM(B7:E7) -> 24 | Q7: =SUM(B7:C7)/P7 -> 0.16666667
A8: G | B8: =SUMIF(result_20260622!$B:$B,sum_pos_20260622!$A8,INDEX(result_20260622!$A:$Z,0,MATCH(sum_pos_20260622!B$1,result_20260622!$1:$1,0))) -> 0 | C8: =SUMIF(result_20260622!$B:$B,sum_pos_20260622!$A8,INDEX(result_20260622!$A:$Z,0,MATCH(sum_pos_20260622!C$1,result_20260622!$1:$1,0))) -> 2 | D8: =SUMIF(result_20260622!$B:$B,sum_pos_20260622!$A8,INDEX(result_20260622!$A:$Z,0,MATCH(sum_pos_20260622!D$1,result_20260622!$1:$1,0))) -> 2 | E8: =SUMIF(result_20260622!$B:$B,sum_pos_20260622!$A8,INDEX(result_20260622!$A:$Z,0,MATCH(sum_pos_20260622!E$1,result_20260622!$1:$1,0))) -> 20 | F8: =SUMIF(result_20260622!$B:$B,sum_pos_20260622!$A8,INDEX(result_20260622!$A:$Z,0,MATCH(sum_pos_20260622!F$1,result_20260622!$1:$1,0))) -> 2 | G8: =SUMIF(result_20260622!$B:$B,sum_pos_20260622!$A8,INDEX(result_20260622!$A:$Z,0,MATCH(sum_pos_20260622!G$1,result_20260622!$1:$1,0))) -> 0 | H8: =SUMIF(result_20260622!$B:$B,sum_pos_20260622!$A8,INDEX(result_20260622!$A:$Z,0,MATCH(sum_pos_20260622!H$1,result_20260622!$1:$1,0))) -> 0 | I8: =SUMIF(result_20260622!$B:$B,sum_pos_20260622!$A8,INDEX(result_20260622!$A:$Z,0,MATCH(sum_pos_20260622!I$1,result_20260622!$1:$1,0))) -> 20 | ... O8: =SUMIF(result_20260622!$B:$B,sum_pos_20260622!$A8,INDEX(result_20260622!$A:$Z,0,MATCH(sum_pos_20260622!O$1,result_20260622!$1:$1,0))) -> 0 | P8: =SUM(B8:E8) -> 24 | Q8: =SUM(B8:C8)/P8 -> 0.083333333
A9: H | B9: =SUMIF(result_20260622!$B:$B,sum_pos_20260622!$A9,INDEX(result_20260622!$A:$Z,0,MATCH(sum_pos_20260622!B$1,result_20260622!$1:$1,0))) -> 0 | C9: =SUMIF(result_20260622!$B:$B,sum_pos_20260622!$A9,INDEX(result_20260622!$A:$Z,0,MATCH(sum_pos_20260622!C$1,result_20260622!$1:$1,0))) -> 0 | D9: =SUMIF(result_20260622!$B:$B,sum_pos_20260622!$A9,INDEX(result_20260622!$A:$Z,0,MATCH(sum_pos_20260622!D$1,result_20260622!$1:$1,0))) -> 0 | E9: =SUMIF(result_20260622!$B:$B,sum_pos_20260622!$A9,INDEX(result_20260622!$A:$Z,0,MATCH(sum_pos_20260622!E$1,result_20260622!$1:$1,0))) -> 0 | F9: =SUMIF(result_20260622!$B:$B,sum_pos_20260622!$A9,INDEX(result_20260622!$A:$Z,0,MATCH(sum_pos_20260622!F$1,result_20260622!$1:$1,0))) -> 0 | G9: =SUMIF(result_20260622!$B:$B,sum_pos_20260622!$A9,INDEX(result_20260622!$A:$Z,0,MATCH(sum_pos_20260622!G$1,result_20260622!$1:$1,0))) -> 0 | H9: =SUMIF(result_20260622!$B:$B,sum_pos_20260622!$A9,INDEX(result_20260622!$A:$Z,0,MATCH(sum_pos_20260622!H$1,result_20260622!$1:$1,0))) -> 0 | I9: =SUMIF(result_20260622!$B:$B,sum_pos_20260622!$A9,INDEX(result_20260622!$A:$Z,0,MATCH(sum_pos_20260622!I$1,result_20260622!$1:$1,0))) -> 0 | ... O9: =SUMIF(result_20260622!$B:$B,sum_pos_20260622!$A9,INDEX(result_20260622!$A:$Z,0,MATCH(sum_pos_20260622!O$1,result_20260622!$1:$1,0))) -> 0 | P9: =SUM(B9:E9) -> 0 | Q9: =SUM(B9:C9)/P9 -> #DIV/0!
A10: I | B10: =SUMIF(result_20260622!$B:$B,sum_pos_20260622!$A10,INDEX(result_20260622!$A:$Z,0,MATCH(sum_pos_20260622!B$1,result_20260622!$1:$1,0))) -> 0 | C10: =SUMIF(result_20260622!$B:$B,sum_pos_20260622!$A10,INDEX(result_20260622!$A:$Z,0,MATCH(sum_pos_20260622!C$1,result_20260622!$1:$1,0))) -> 4 | D10: =SUMIF(result_20260622!$B:$B,sum_pos_20260622!$A10,INDEX(result_20260622!$A:$Z,0,MATCH(sum_pos_20260622!D$1,result_20260622!$1:$1,0))) -> 1 | E10: =SUMIF(result_20260622!$B:$B,sum_pos_20260622!$A10,INDEX(result_20260622!$A:$Z,0,MATCH(sum_pos_20260622!E$1,result_20260622!$1:$1,0))) -> 19 | F10: =SUMIF(result_20260622!$B:$B,sum_pos_20260622!$A10,INDEX(result_20260622!$A:$Z,0,MATCH(sum_pos_20260622!F$1,result_20260622!$1:$1,0))) -> 1 | G10: =SUMIF(result_20260622!$B:$B,sum_pos_20260622!$A10,INDEX(result_20260622!$A:$Z,0,MATCH(sum_pos_20260622!G$1,result_20260622!$1:$1,0))) -> 0 | H10: =SUMIF(result_20260622!$B:$B,sum_pos_20260622!$A10,INDEX(result_20260622!$A:$Z,0,MATCH(sum_pos_20260622!H$1,result_20260622!$1:$1,0))) -> 1 | I10: =SUMIF(result_20260622!$B:$B,sum_pos_20260622!$A10,INDEX(result_20260622!$A:$Z,0,MATCH(sum_pos_20260622!I$1,result_20260622!$1:$1,0))) -> 18 | ... O10: =SUMIF(result_20260622!$B:$B,sum_pos_20260622!$A10,INDEX(result_20260622!$A:$Z,0,MATCH(sum_pos_20260622!O$1,result_20260622!$1:$1,0))) -> 2 | P10: =SUM(B10:E10) -> 24 | Q10: =SUM(B10:C10)/P10 -> 0.16666667
A11: SUM | B11: =SUM(B2:B10) -> 0 | C11: =SUM(C2:C10) -> 20 | D11: =SUM(D2:D10) -> 10 | E11: =SUM(E2:E10) -> 114 | F11: =SUM(F2:F10) -> 4 | G11: =SUM(G2:G10) -> 0 | H11: =SUM(H2:H10) -> 2 | I11: =SUM(I2:I10) -> 101 | ... P11: =SUM(P2:P10) -> 144 | Q11: =SUM(B11+C11)/P11 -> 0.13888889
A13: Excluding Pos. B, E, H
A14: Position | B14: Success | C14: Success after intervention | D14: Success if further action were taken | E14: Failed | F14: Grasp point not good, potential failure | G14: No poses generated | H14: Fell during turning around | I14: Grasp too loose | J14: Grasp point too high, placement needs manual adjustment | K14: Grasp point too low, placement distant from holder | L14: Grasp in opposite direction | M14: Possible collision between links | N14: Grasp aborted due to joint limits | O14: Object not face out after placement | P14: Trials | Q14: Success rate(S+PS)
A15: A | B15: =SUMIF(result_20260622!$B:$B,sum_pos_20260622!$A15,INDEX(result_20260622!$A:$Z,0,MATCH(sum_pos_20260622!B$1,result_20260622!$1:$1,0))) -> 0 | C15: =SUMIF(result_20260622!$B:$B,sum_pos_20260622!$A15,INDEX(result_20260622!$A:$Z,0,MATCH(sum_pos_20260622!C$1,result_20260622!$1:$1,0))) -> 4 | D15: =SUMIF(result_20260622!$B:$B,sum_pos_20260622!$A15,INDEX(result_20260622!$A:$Z,0,MATCH(sum_pos_20260622!D$1,result_20260622!$1:$1,0))) -> 2 | E15: =SUMIF(result_20260622!$B:$B,sum_pos_20260622!$A15,INDEX(result_20260622!$A:$Z,0,MATCH(sum_pos_20260622!E$1,result_20260622!$1:$1,0))) -> 18 | F15: =SUMIF(result_20260622!$B:$B,sum_pos_20260622!$A15,INDEX(result_20260622!$A:$Z,0,MATCH(sum_pos_20260622!F$1,result_20260622!$1:$1,0))) -> 0 | G15: =SUMIF(result_20260622!$B:$B,sum_pos_20260622!$A15,INDEX(result_20260622!$A:$Z,0,MATCH(sum_pos_20260622!G$1,result_20260622!$1:$1,0))) -> 0 | H15: =SUMIF(result_20260622!$B:$B,sum_pos_20260622!$A15,INDEX(result_20260622!$A:$Z,0,MATCH(sum_pos_20260622!H$1,result_20260622!$1:$1,0))) -> 0 | I15: =SUMIF(result_20260622!$B:$B,sum_pos_20260622!$A15,INDEX(result_20260622!$A:$Z,0,MATCH(sum_pos_20260622!I$1,result_20260622!$1:$1,0))) -> 16 | ... O15: =SUMIF(result_20260622!$B:$B,sum_pos_20260622!$A15,INDEX(result_20260622!$A:$Z,0,MATCH(sum_pos_20260622!O$1,result_20260622!$1:$1,0))) -> 0 | P15: =SUM(B15:E15) -> 24 | Q15: =SUM(B15:C15)/P15 -> 0.16666667
A16: C | B16: =SUMIF(result_20260622!$B:$B,sum_pos_20260622!$A16,INDEX(result_20260622!$A:$Z,0,MATCH(sum_pos_20260622!B$1,result_20260622!$1:$1,0))) -> 0 | C16: =SUMIF(result_20260622!$B:$B,sum_pos_20260622!$A16,INDEX(result_20260622!$A:$Z,0,MATCH(sum_pos_20260622!C$1,result_20260622!$1:$1,0))) -> 4 | D16: =SUMIF(result_20260622!$B:$B,sum_pos_20260622!$A16,INDEX(result_20260622!$A:$Z,0,MATCH(sum_pos_20260622!D$1,result_20260622!$1:$1,0))) -> 0 | E16: =SUMIF(result_20260622!$B:$B,sum_pos_20260622!$A16,INDEX(result_20260622!$A:$Z,0,MATCH(sum_pos_20260622!E$1,result_20260622!$1:$1,0))) -> 20 | F16: =SUMIF(result_20260622!$B:$B,sum_pos_20260622!$A16,INDEX(result_20260622!$A:$Z,0,MATCH(sum_pos_20260622!F$1,result_20260622!$1:$1,0))) -> 0 | G16: =SUMIF(result_20260622!$B:$B,sum_pos_20260622!$A16,INDEX(result_20260622!$A:$Z,0,MATCH(sum_pos_20260622!G$1,result_20260622!$1:$1,0))) -> 0 | H16: =SUMIF(result_20260622!$B:$B,sum_pos_20260622!$A16,INDEX(result_20260622!$A:$Z,0,MATCH(sum_pos_20260622!H$1,result_20260622!$1:$1,0))) -> 0 | I16: =SUMIF(result_20260622!$B:$B,sum_pos_20260622!$A16,INDEX(result_20260622!$A:$Z,0,MATCH(sum_pos_20260622!I$1,result_20260622!$1:$1,0))) -> 17 | ... O16: =SUMIF(result_20260622!$B:$B,sum_pos_20260622!$A16,INDEX(result_20260622!$A:$Z,0,MATCH(sum_pos_20260622!O$1,result_20260622!$1:$1,0))) -> 0 | P16: =SUM(B16:E16) -> 24 | Q16: =SUM(B16:C16)/P16 -> 0.16666667
A17: D | B17: =SUMIF(result_20260622!$B:$B,sum_pos_20260622!$A17,INDEX(result_20260622!$A:$Z,0,MATCH(sum_pos_20260622!B$1,result_20260622!$1:$1,0))) -> 0 | C17: =SUMIF(result_20260622!$B:$B,sum_pos_20260622!$A17,INDEX(result_20260622!$A:$Z,0,MATCH(sum_pos_20260622!C$1,result_20260622!$1:$1,0))) -> 2 | D17: =SUMIF(result_20260622!$B:$B,sum_pos_20260622!$A17,INDEX(result_20260622!$A:$Z,0,MATCH(sum_pos_20260622!D$1,result_20260622!$1:$1,0))) -> 3 | E17: =SUMIF(result_20260622!$B:$B,sum_pos_20260622!$A17,INDEX(result_20260622!$A:$Z,0,MATCH(sum_pos_20260622!E$1,result_20260622!$1:$1,0))) -> 19 | F17: =SUMIF(result_20260622!$B:$B,sum_pos_20260622!$A17,INDEX(result_20260622!$A:$Z,0,MATCH(sum_pos_20260622!F$1,result_20260622!$1:$1,0))) -> 1 | G17: =SUMIF(result_20260622!$B:$B,sum_pos_20260622!$A17,INDEX(result_20260622!$A:$Z,0,MATCH(sum_pos_20260622!G$1,result_20260622!$1:$1,0))) -> 0 | H17: =SUMIF(result_20260622!$B:$B,sum_pos_20260622!$A17,INDEX(result_20260622!$A:$Z,0,MATCH(sum_pos_20260622!H$1,result_20260622!$1:$1,0))) -> 1 | I17: =SUMIF(result_20260622!$B:$B,sum_pos_20260622!$A17,INDEX(result_20260622!$A:$Z,0,MATCH(sum_pos_20260622!I$1,result_20260622!$1:$1,0))) -> 15 | ... O17: =SUMIF(result_20260622!$B:$B,sum_pos_20260622!$A17,INDEX(result_20260622!$A:$Z,0,MATCH(sum_pos_20260622!O$1,result_20260622!$1:$1,0))) -> 0 | P17: =SUM(B17:E17) -> 24 | Q17: =SUM(B17:C17)/P17 -> 0.083333333
A18: F | B18: =SUMIF(result_20260622!$B:$B,sum_pos_20260622!$A18,INDEX(result_20260622!$A:$Z,0,MATCH(sum_pos_20260622!B$1,result_20260622!$1:$1,0))) -> 0 | C18: =SUMIF(result_20260622!$B:$B,sum_pos_20260622!$A18,INDEX(result_20260622!$A:$Z,0,MATCH(sum_pos_20260622!C$1,result_20260622!$1:$1,0))) -> 4 | D18: =SUMIF(result_20260622!$B:$B,sum_pos_20260622!$A18,INDEX(result_20260622!$A:$Z,0,MATCH(sum_pos_20260622!D$1,result_20260622!$1:$1,0))) -> 2 | E18: =SUMIF(result_20260622!$B:$B,sum_pos_20260622!$A18,INDEX(result_20260622!$A:$Z,0,MATCH(sum_pos_20260622!E$1,result_20260622!$1:$1,0))) -> 18 | F18: =SUMIF(result_20260622!$B:$B,sum_pos_20260622!$A18,INDEX(result_20260622!$A:$Z,0,MATCH(sum_pos_20260622!F$1,result_20260622!$1:$1,0))) -> 0 | G18: =SUMIF(result_20260622!$B:$B,sum_pos_20260622!$A18,INDEX(result_20260622!$A:$Z,0,MATCH(sum_pos_20260622!G$1,result_20260622!$1:$1,0))) -> 0 | H18: =SUMIF(result_20260622!$B:$B,sum_pos_20260622!$A18,INDEX(result_20260622!$A:$Z,0,MATCH(sum_pos_20260622!H$1,result_20260622!$1:$1,0))) -> 0 | I18: =SUMIF(result_20260622!$B:$B,sum_pos_20260622!$A18,INDEX(result_20260622!$A:$Z,0,MATCH(sum_pos_20260622!I$1,result_20260622!$1:$1,0))) -> 15 | ... O18: =SUMIF(result_20260622!$B:$B,sum_pos_20260622!$A18,INDEX(result_20260622!$A:$Z,0,MATCH(sum_pos_20260622!O$1,result_20260622!$1:$1,0))) -> 0 | P18: =SUM(B18:E18) -> 24 | Q18: =SUM(B18:C18)/P18 -> 0.16666667
A19: G | B19: =SUMIF(result_20260622!$B:$B,sum_pos_20260622!$A19,INDEX(result_20260622!$A:$Z,0,MATCH(sum_pos_20260622!B$1,result_20260622!$1:$1,0))) -> 0 | C19: =SUMIF(result_20260622!$B:$B,sum_pos_20260622!$A19,INDEX(result_20260622!$A:$Z,0,MATCH(sum_pos_20260622!C$1,result_20260622!$1:$1,0))) -> 2 | D19: =SUMIF(result_20260622!$B:$B,sum_pos_20260622!$A19,INDEX(result_20260622!$A:$Z,0,MATCH(sum_pos_20260622!D$1,result_20260622!$1:$1,0))) -> 2 | E19: =SUMIF(result_20260622!$B:$B,sum_pos_20260622!$A19,INDEX(result_20260622!$A:$Z,0,MATCH(sum_pos_20260622!E$1,result_20260622!$1:$1,0))) -> 20 | F19: =SUMIF(result_20260622!$B:$B,sum_pos_20260622!$A19,INDEX(result_20260622!$A:$Z,0,MATCH(sum_pos_20260622!F$1,result_20260622!$1:$1,0))) -> 2 | G19: =SUMIF(result_20260622!$B:$B,sum_pos_20260622!$A19,INDEX(result_20260622!$A:$Z,0,MATCH(sum_pos_20260622!G$1,result_20260622!$1:$1,0))) -> 0 | H19: =SUMIF(result_20260622!$B:$B,sum_pos_20260622!$A19,INDEX(result_20260622!$A:$Z,0,MATCH(sum_pos_20260622!H$1,result_20260622!$1:$1,0))) -> 0 | I19: =SUMIF(result_20260622!$B:$B,sum_pos_20260622!$A19,INDEX(result_20260622!$A:$Z,0,MATCH(sum_pos_20260622!I$1,result_20260622!$1:$1,0))) -> 20 | ... O19: =SUMIF(result_20260622!$B:$B,sum_pos_20260622!$A19,INDEX(result_20260622!$A:$Z,0,MATCH(sum_pos_20260622!O$1,result_20260622!$1:$1,0))) -> 0 | P19: =SUM(B19:E19) -> 24 | Q19: =SUM(B19:C19)/P19 -> 0.083333333
A20: I | B20: =SUMIF(result_20260622!$B:$B,sum_pos_20260622!$A20,INDEX(result_20260622!$A:$Z,0,MATCH(sum_pos_20260622!B$1,result_20260622!$1:$1,0))) -> 0 | C20: =SUMIF(result_20260622!$B:$B,sum_pos_20260622!$A20,INDEX(result_20260622!$A:$Z,0,MATCH(sum_pos_20260622!C$1,result_20260622!$1:$1,0))) -> 4 | D20: =SUMIF(result_20260622!$B:$B,sum_pos_20260622!$A20,INDEX(result_20260622!$A:$Z,0,MATCH(sum_pos_20260622!D$1,result_20260622!$1:$1,0))) -> 1 | E20: =SUMIF(result_20260622!$B:$B,sum_pos_20260622!$A20,INDEX(result_20260622!$A:$Z,0,MATCH(sum_pos_20260622!E$1,result_20260622!$1:$1,0))) -> 19 | F20: =SUMIF(result_20260622!$B:$B,sum_pos_20260622!$A20,INDEX(result_20260622!$A:$Z,0,MATCH(sum_pos_20260622!F$1,result_20260622!$1:$1,0))) -> 1 | G20: =SUMIF(result_20260622!$B:$B,sum_pos_20260622!$A20,INDEX(result_20260622!$A:$Z,0,MATCH(sum_pos_20260622!G$1,result_20260622!$1:$1,0))) -> 0 | H20: =SUMIF(result_20260622!$B:$B,sum_pos_20260622!$A20,INDEX(result_20260622!$A:$Z,0,MATCH(sum_pos_20260622!H$1,result_20260622!$1:$1,0))) -> 1 | I20: =SUMIF(result_20260622!$B:$B,sum_pos_20260622!$A20,INDEX(result_20260622!$A:$Z,0,MATCH(sum_pos_20260622!I$1,result_20260622!$1:$1,0))) -> 18 | ... O20: =SUMIF(result_20260622!$B:$B,sum_pos_20260622!$A20,INDEX(result_20260622!$A:$Z,0,MATCH(sum_pos_20260622!O$1,result_20260622!$1:$1,0))) -> 2 | P20: =SUM(B20:E20) -> 24 | Q20: =SUM(B20:C20)/P20 -> 0.16666667
A21: SUM | B21: =SUM(B15:B20) -> 0 | C21: =SUM(C15:C20) -> 20 | D21: =SUM(D15:D20) -> 10 | E21: =SUM(E15:E20) -> 114 | F21: =SUM(F15:F20) -> 4 | G21: =SUM(G15:G20) -> 0 | H21: =SUM(H15:H20) -> 2 | I21: =SUM(I15:I20) -> 101 | ... P21: =SUM(P15:P20) -> 144 | Q21: =SUM(B21+C21)/P21 -> 0.13888889

Sheet sum_fail_20260622
A1: Failure reason | B1: Count | C1: Percentage | F1: Orientation | G1: sum | H1: F1 | I1: F2 | J1: F3 | K1: F4 | L1: F5 | M1: F1/% | N1: F2/% | O1: F3/% | P1: F4/% | Q1: F5/% | R1: Dominant
A2: Grasp too loose | B2: =result_20260622!I146 -> 101 | C2: =B2/$B$21 -> 0.70138889 | F2: 1 | G2: {=SUMPRODUCT((result_20260622!$A$2:$A$182=sum_fail_20260622!$F2)*result_20260622!$I$2:$R$182)} -> 18 | H2: {=SUMPRODUCT((result_20260622!$A$2:$A$182=sum_fail_20260622!$F2)*result_20260622!$I$2:$J$182)} -> 10 | I2: {=SUMPRODUCT((result_20260622!$A$2:$A$182=sum_fail_20260622!$F2)*result_20260622!$K$2:$K$182)} -> 0 | J2: {=SUMPRODUCT((result_20260622!$A$2:$A$182=sum_fail_20260622!$F2)*result_20260622!$L$2:$M$182)} -> 0 | K2: {=SUMPRODUCT((result_20260622!$A$2:$A$182=sum_fail_20260622!$F2)*result_20260622!$N$2:$N$182)} -> 2 | L2: {=SUMPRODUCT((result_20260622!$A$2:$A$182=sum_fail_20260622!$F2)*result_20260622!$O$2:$R$182)} -> 6 | M2: =H2/$G2 -> 0.55555556 | N2: =I2/$G2 -> 0 | O2: =J2/$G2 -> 0 | P2: =K2/$G2 -> 0.11111111 | Q2: =L2/$G2 -> 0.33333333 | R2: F1
A3: Object fell during turning around | B3: =result_20260622!J146 -> 2 | C3: =B3/$B$21 -> 0.013888889 | F3: 2 | G3: {=SUMPRODUCT((result_20260622!$A$2:$A$182=sum_fail_20260622!$F3)*result_20260622!$I$2:$R$182)} -> 18 | H3: {=SUMPRODUCT((result_20260622!$A$2:$A$182=sum_fail_20260622!$F3)*result_20260622!$I$2:$J$182)} -> 14 | I3: {=SUMPRODUCT((result_20260622!$A$2:$A$182=sum_fail_20260622!$F3)*result_20260622!$K$2:$K$182)} -> 0 | J3: {=SUMPRODUCT((result_20260622!$A$2:$A$182=sum_fail_20260622!$F3)*result_20260622!$L$2:$M$182)} -> 0 | K3: {=SUMPRODUCT((result_20260622!$A$2:$A$182=sum_fail_20260622!$F3)*result_20260622!$N$2:$N$182)} -> 2 | L3: {=SUMPRODUCT((result_20260622!$A$2:$A$182=sum_fail_20260622!$F3)*result_20260622!$O$2:$R$182)} -> 2 | M3: =H3/$G3 -> 0.77777778 | N3: =I3/$G3 -> 0 | O3: =J3/$G3 -> 0 | P3: =K3/$G3 -> 0.11111111 | Q3: =L3/$G3 -> 0.11111111 | R3: F1
A4: No poses generated | B4: =result_20260622!K146 -> 0 | C4: =B4/$B$21 -> 0 | F4: 3 | G4: {=SUMPRODUCT((result_20260622!$A$2:$A$182=sum_fail_20260622!$F4)*result_20260622!$I$2:$R$182)} -> 18 | H4: {=SUMPRODUCT((result_20260622!$A$2:$A$182=sum_fail_20260622!$F4)*result_20260622!$I$2:$J$182)} -> 18 | I4: {=SUMPRODUCT((result_20260622!$A$2:$A$182=sum_fail_20260622!$F4)*result_20260622!$K$2:$K$182)} -> 0 | J4: {=SUMPRODUCT((result_20260622!$A$2:$A$182=sum_fail_20260622!$F4)*result_20260622!$L$2:$M$182)} -> 0 | K4: {=SUMPRODUCT((result_20260622!$A$2:$A$182=sum_fail_20260622!$F4)*result_20260622!$N$2:$N$182)} -> 0 | L4: {=SUMPRODUCT((result_20260622!$A$2:$A$182=sum_fail_20260622!$F4)*result_20260622!$O$2:$R$182)} -> 0 | M4: =H4/$G4 -> 1 | N4: =I4/$G4 -> 0 | O4: =J4/$G4 -> 0 | P4: =K4/$G4 -> 0 | Q4: =L4/$G4 -> 0 | R4: F1
A5: Possible collision between links | B5: =result_20260622!L146 -> 11 | C5: =B5/$B$21 -> 0.076388889 | F5: 4 | G5: {=SUMPRODUCT((result_20260622!$A$2:$A$182=sum_fail_20260622!$F5)*result_20260622!$I$2:$R$182)} -> 18 | H5: {=SUMPRODUCT((result_20260622!$A$2:$A$182=sum_fail_20260622!$F5)*result_20260622!$I$2:$J$182)} -> 14 | I5: {=SUMPRODUCT((result_20260622!$A$2:$A$182=sum_fail_20260622!$F5)*result_20260622!$K$2:$K$182)} -> 0 | J5: {=SUMPRODUCT((result_20260622!$A$2:$A$182=sum_fail_20260622!$F5)*result_20260622!$L$2:$M$182)} -> 0 | K5: {=SUMPRODUCT((result_20260622!$A$2:$A$182=sum_fail_20260622!$F5)*result_20260622!$N$2:$N$182)} -> 0 | L5: {=SUMPRODUCT((result_20260622!$A$2:$A$182=sum_fail_20260622!$F5)*result_20260622!$O$2:$R$182)} -> 4 | M5: =H5/$G5 -> 0.77777778 | N5: =I5/$G5 -> 0 | O5: =J5/$G5 -> 0 | P5: =K5/$G5 -> 0 | Q5: =L5/$G5 -> 0.22222222 | R5: F1
A6: Grasp aborted due to joint limits | B6: =result_20260622!M146 -> 0 | C6: =B6/$B$21 -> 0 | F6: 5 | G6: {=SUMPRODUCT((result_20260622!$A$2:$A$182=sum_fail_20260622!$F6)*result_20260622!$I$2:$R$182)} -> 18 | H6: {=SUMPRODUCT((result_20260622!$A$2:$A$182=sum_fail_20260622!$F6)*result_20260622!$I$2:$J$182)} -> 15 | I6: {=SUMPRODUCT((result_20260622!$A$2:$A$182=sum_fail_20260622!$F6)*result_20260622!$K$2:$K$182)} -> 0 | J6: {=SUMPRODUCT((result_20260622!$A$2:$A$182=sum_fail_20260622!$F6)*result_20260622!$L$2:$M$182)} -> 0 | K6: {=SUMPRODUCT((result_20260622!$A$2:$A$182=sum_fail_20260622!$F6)*result_20260622!$N$2:$N$182)} -> 2 | L6: {=SUMPRODUCT((result_20260622!$A$2:$A$182=sum_fail_20260622!$F6)*result_20260622!$O$2:$R$182)} -> 1 | M6: =H6/$G6 -> 0.83333333 | N6: =I6/$G6 -> 0 | O6: =J6/$G6 -> 0 | P6: =K6/$G6 -> 0.11111111 | Q6: =L6/$G6 -> 0.055555556 | R6: F1
A7: Grasp in opposite direction | B7: =result_20260622!N146 -> 10 | C7: =B7/$B$21 -> 0.069444444 | F7: 6 | G7: {=SUMPRODUCT((result_20260622!$A$2:$A$182=sum_fail_20260622!$F7)*result_20260622!$I$2:$R$182)} -> 18 | H7: {=SUMPRODUCT((result_20260622!$A$2:$A$182=sum_fail_20260622!$F7)*result_20260622!$I$2:$J$182)} -> 13 | I7: {=SUMPRODUCT((result_20260622!$A$2:$A$182=sum_fail_20260622!$F7)*result_20260622!$K$2:$K$182)} -> 0 | J7: {=SUMPRODUCT((result_20260622!$A$2:$A$182=sum_fail_20260622!$F7)*result_20260622!$L$2:$M$182)} -> 0 | K7: {=SUMPRODUCT((result_20260622!$A$2:$A$182=sum_fail_20260622!$F7)*result_20260622!$N$2:$N$182)} -> 1 | L7: {=SUMPRODUCT((result_20260622!$A$2:$A$182=sum_fail_20260622!$F7)*result_20260622!$O$2:$R$182)} -> 4 | M7: =H7/$G7 -> 0.72222222 | N7: =I7/$G7 -> 0 | O7: =J7/$G7 -> 0 | P7: =K7/$G7 -> 0.055555556 | Q7: =L7/$G7 -> 0.22222222 | R7: F1
A8: Grasp point not good, potential failure | B8: =result_20260622!O146 -> 4 | C8: =B8/$B$21 -> 0.027777778 | F8: 7 | G8: {=SUMPRODUCT((result_20260622!$A$2:$A$182=sum_fail_20260622!$F8)*result_20260622!$I$2:$R$182)} -> 18 | H8: {=SUMPRODUCT((result_20260622!$A$2:$A$182=sum_fail_20260622!$F8)*result_20260622!$I$2:$J$182)} -> 5 | I8: {=SUMPRODUCT((result_20260622!$A$2:$A$182=sum_fail_20260622!$F8)*result_20260622!$K$2:$K$182)} -> 0 | J8: {=SUMPRODUCT((result_20260622!$A$2:$A$182=sum_fail_20260622!$F8)*result_20260622!$L$2:$M$182)} -> 11 | K8: {=SUMPRODUCT((result_20260622!$A$2:$A$182=sum_fail_20260622!$F8)*result_20260622!$N$2:$N$182)} -> 0 | L8: {=SUMPRODUCT((result_20260622!$A$2:$A$182=sum_fail_20260622!$F8)*result_20260622!$O$2:$R$182)} -> 2 | M8: =H8/$G8 -> 0.27777778 | N8: =I8/$G8 -> 0 | O8: =J8/$G8 -> 0.61111111 | P8: =K8/$G8 -> 0 | Q8: =L8/$G8 -> 0.11111111 | R8: F3
A9: Grasp point too high, placement needs manual adjustment | B9: =result_20260622!P146 -> 6 | C9: =B9/$B$21 -> 0.041666667 | F9: 8 | G9: {=SUMPRODUCT((result_20260622!$A$2:$A$182=sum_fail_20260622!$F9)*result_20260622!$I$2:$R$182)} -> 18 | H9: {=SUMPRODUCT((result_20260622!$A$2:$A$182=sum_fail_20260622!$F9)*result_20260622!$I$2:$J$182)} -> 14 | I9: {=SUMPRODUCT((result_20260622!$A$2:$A$182=sum_fail_20260622!$F9)*result_20260622!$K$2:$K$182)} -> 0 | J9: {=SUMPRODUCT((result_20260622!$A$2:$A$182=sum_fail_20260622!$F9)*result_20260622!$L$2:$M$182)} -> 0 | K9: {=SUMPRODUCT((result_20260622!$A$2:$A$182=sum_fail_20260622!$F9)*result_20260622!$N$2:$N$182)} -> 3 | L9: {=SUMPRODUCT((result_20260622!$A$2:$A$182=sum_fail_20260622!$F9)*result_20260622!$O$2:$R$182)} -> 1 | M9: =H9/$G9 -> 0.77777778 | N9: =I9/$G9 -> 0 | O9: =J9/$G9 -> 0 | P9: =K9/$G9 -> 0.16666667 | Q9: =L9/$G9 -> 0.055555556 | R9: F1
A10: Grasp point too low, placement distant from holder | B10: =result_20260622!Q146 -> 8 | C10: =B10/$B$21 -> 0.055555556 | G10: =SUM(G2:G9) -> 144 | H10: =SUM(H2:H9) -> 103 | I10: =SUM(I2:I9) -> 0 | J10: =SUM(J2:J9) -> 11 | K10: =SUM(K2:K9) -> 10 | L10: =SUM(L2:L9) -> 20
A11: Object not face out after placement | B11: =result_20260611!R146 -> 0 | C11: =B11/$B$21 -> 0
F12: Position | G12: sum | H12: F1 | I12: F2 | J12: F3 | K12: F4 | L12: F5
F13: A | G13: {=SUMPRODUCT((result_20260622!$B$2:$B$182=sum_fail_20260622!$F13)*result_20260622!$I$2:$R$182)} -> 24 | H13: {=SUMPRODUCT((result_20260622!$B$2:$B$182=sum_fail_20260622!$F13)*result_20260622!$I$2:$J$182)} -> 16 | I13: {=SUMPRODUCT((result_20260622!$B$2:$B$182=sum_fail_20260622!$F13)*result_20260622!$K$2:$K$182)} -> 0 | J13: {=SUMPRODUCT((result_20260622!$B$2:$B$182=sum_fail_20260622!$F13)*result_20260622!$L$2:$M$182)} -> 2 | K13: {=SUMPRODUCT((result_20260622!$B$2:$B$182=sum_fail_20260622!$F13)*result_20260622!$N$2:$N$182)} -> 3 | L13: {=SUMPRODUCT((result_20260622!$B$2:$B$182=sum_fail_20260622!$F13)*result_20260622!$O$2:$R$182)} -> 3
F14: C | G14: {=SUMPRODUCT((result_20260622!$B$2:$B$182=sum_fail_20260622!$F14)*result_20260622!$I$2:$R$182)} -> 24 | H14: {=SUMPRODUCT((result_20260622!$B$2:$B$182=sum_fail_20260622!$F14)*result_20260622!$I$2:$J$182)} -> 17 | I14: {=SUMPRODUCT((result_20260622!$B$2:$B$182=sum_fail_20260622!$F14)*result_20260622!$K$2:$K$182)} -> 0 | J14: {=SUMPRODUCT((result_20260622!$B$2:$B$182=sum_fail_20260622!$F14)*result_20260622!$L$2:$M$182)} -> 3 | K14: {=SUMPRODUCT((result_20260622!$B$2:$B$182=sum_fail_20260622!$F14)*result_20260622!$N$2:$N$182)} -> 3 | L14: {=SUMPRODUCT((result_20260622!$B$2:$B$182=sum_fail_20260622!$F14)*result_20260622!$O$2:$R$182)} -> 1
A15: Success | B15: =result_20260622!E146 -> 0 | F15: D | G15: {=SUMPRODUCT((result_20260622!$B$2:$B$182=sum_fail_20260622!$F15)*result_20260622!$I$2:$R$182)} -> 24 | H15: {=SUMPRODUCT((result_20260622!$B$2:$B$182=sum_fail_20260622!$F15)*result_20260622!$I$2:$J$182)} -> 16 | I15: {=SUMPRODUCT((result_20260622!$B$2:$B$182=sum_fail_20260622!$F15)*result_20260622!$K$2:$K$182)} -> 0 | J15: {=SUMPRODUCT((result_20260622!$B$2:$B$182=sum_fail_20260622!$F15)*result_20260622!$L$2:$M$182)} -> 3 | K15: {=SUMPRODUCT((result_20260622!$B$2:$B$182=sum_fail_20260622!$F15)*result_20260622!$N$2:$N$182)} -> 1 | L15: {=SUMPRODUCT((result_20260622!$B$2:$B$182=sum_fail_20260622!$F15)*result_20260622!$O$2:$R$182)} -> 4
A16: Success after intervention | B16: =result_20260622!F146 -> 20 | F16: F | G16: {=SUMPRODUCT((result_20260622!$B$2:$B$182=sum_fail_20260622!$F16)*result_20260622!$I$2:$R$182)} -> 24 | H16: {=SUMPRODUCT((result_20260622!$B$2:$B$182=sum_fail_20260622!$F16)*result_20260622!$I$2:$J$182)} -> 15 | I16: {=SUMPRODUCT((result_20260622!$B$2:$B$182=sum_fail_20260622!$F16)*result_20260622!$K$2:$K$182)} -> 0 | J16: {=SUMPRODUCT((result_20260622!$B$2:$B$182=sum_fail_20260622!$F16)*result_20260622!$L$2:$M$182)} -> 3 | K16: {=SUMPRODUCT((result_20260622!$B$2:$B$182=sum_fail_20260622!$F16)*result_20260622!$N$2:$N$182)} -> 0 | L16: {=SUMPRODUCT((result_20260622!$B$2:$B$182=sum_fail_20260622!$F16)*result_20260622!$O$2:$R$182)} -> 6
A17: Success if further action were taken | B17: =result_20260622!G146 -> 10 | F17: G | G17: {=SUMPRODUCT((result_20260622!$B$2:$B$182=sum_fail_20260622!$F17)*result_20260622!$I$2:$R$182)} -> 24 | H17: {=SUMPRODUCT((result_20260622!$B$2:$B$182=sum_fail_20260622!$F17)*result_20260622!$I$2:$J$182)} -> 20 | I17: {=SUMPRODUCT((result_20260622!$B$2:$B$182=sum_fail_20260622!$F17)*result_20260622!$K$2:$K$182)} -> 0 | J17: {=SUMPRODUCT((result_20260622!$B$2:$B$182=sum_fail_20260622!$F17)*result_20260622!$L$2:$M$182)} -> 0 | K17: {=SUMPRODUCT((result_20260622!$B$2:$B$182=sum_fail_20260622!$F17)*result_20260622!$N$2:$N$182)} -> 2 | L17: {=SUMPRODUCT((result_20260622!$B$2:$B$182=sum_fail_20260622!$F17)*result_20260622!$O$2:$R$182)} -> 2
